<sdf version="1.6">
<model name='adeept_awr' canonical_link='chassis'>
    <pose>0 0 1 0 0 0</pose>
        <link name='chassis'>
        <pose relative_to='__model__'>0 0 0.2 0 0 0</pose>
        
        <inertial>
            <mass>2</mass>
            <inertia>
                <ixx>0.003338</ixx>
                <iyy>0.004204</iyy>
                <izz>0.005667</izz>
            </inertia>
        </inertial>

        <visual name='visual'>
            <geometry>
                <box>
                    <size>0.14 0.12 0.075</size>
                </box>
            </geometry>
            <material>
                <ambient>0.0 0.0 1.0 1</ambient>
                <diffuse>0.0 0.0 1.0 1</diffuse>
                <specular>0.0 0.0 1.0 1</specular>
            </material>
        </visual>
        <collision name='collision'>
            <geometry>
                <box>
                    <size>0.14 0.12 0.075</size>
                </box>
            </geometry>
        </collision>
        </link>

        <link name='camera'>
            <pose relative_to='chassis'>0.065 0 0.03 0 0 0</pose>
            <inertial>
                <mass>0.01</mass>
                <inertia>
                    <ixx>3.4725e-06</ixx>
                    <iyy>4.21875e-06</iyy>
                    <izz>5.385e-06</izz>
                </inertia>
            </inertial>
            <visual name='visual'>
                <geometry>
                    <box>
                        <size>0.02 0.045 0.03</size>
                    </box>
                </geometry>
                <material>
                    <ambient>0.0 1.0 0.0 1</ambient>
                    <diffuse>0.0 1.0 0.0 1</diffuse>
                    <specular>0.0 1.0 0.0 1</specular>
                </material>
            </visual>
            <collision name='collision'>
                <geometry>
                    <box>
                        <size>0.02 0.045 0.03</size>
                    </box>
                </geometry>
            </collision>
            
            <sensor name='camera' type='camera'>
                <topic>simulator_camera</topic>
                <update_rate>30</update_rate>
                <camera name='__default__'>
                    <horizontal_fov>1.0469999999999999</horizontal_fov>
                    <image>
                        <width>960</width>
                        <height>540</height>
                        <format>RGB_INT8</format>
                    </image>
                    <clip>
                        <near>0.01</near>
                        <far>100</far>
                    </clip>
                    <visibility_mask>4294967295</visibility_mask>
                    <lens>
                        <type>stereographic</type>
                        <scale_to_hfov>true</scale_to_hfov>
                        <cutoff_angle>1.5708</cutoff_angle>
                        <env_texture_size>256</env_texture_size>
                    </lens>
                </camera>
            </sensor>
        </link>

        <joint name='camera_servo_joint' type='revolute'>
            <pose relative_to='camera'/>
            <parent>chassis</parent>
            <child>camera</child>
            <axis>
                <xyz>0 1 0</xyz>
                <limit>
                    <lower>-1.57076</lower>
                    <upper>0.1745</upper>
                </limit>
                <effort>
                    <min>-10</min>
                    <max>10</max>
                </effort>
            </axis>
        </joint>

        <plugin name="ignition::gazebo::systems::JointController" filename="libignition-gazebo-joint-controller-system.so">
            <joint_name>camera_servo_joint</joint_name>
        </plugin>
        
        <link name='lidar'>
            <pose relative_to='chassis'>0 0 0.0425 0 0 0</pose>
            <inertial>
                <mass>0.05</mass>
                <inertia>
                    <ixx>8.3333e-09</ixx>
                    <iyy>8.3333e-09</iyy>
                    <izz>8.3333e-09</izz>
                  </inertia>
            </inertial>
            <visual name='visual'>
                <geometry>
                  <box>
                    <size>0.01 0.01 0.01</size>
                  </box>
                </geometry>
                <material>
                    <ambient>0.9 0.9 0.9 1</ambient>
                    <diffuse>0.9 0.9 0.9 1</diffuse>
                    <specular>0.9 0.9 0.9 1</specular>
                </material>
              </visual>
            <collision name='collision'>
              <geometry>
                <box>
                  <size>0.01 0.01 0.01</size>
                </box>
              </geometry>
            </collision>

            <sensor name='gpu_lidar' type='gpu_lidar'>
              <topic>simulator_lidar</topic>
              <update_rate>20</update_rate>
              <lidar>
                <scan>
                  <horizontal>
                    <samples>360</samples>
                    <resolution>1</resolution>
                    <min_angle>-3.14</min_angle>
                    <max_angle>3.14</max_angle>
                  </horizontal>

                  <vertical>
                    <samples>1</samples>
                    <resolution>1</resolution>
                    <min_angle>0</min_angle>
                    <max_angle>0</max_angle>
                  </vertical>
                </scan>
                <range>
                  <min>0.08</min>
                  <max>10</max>
                  <resolution>0.01</resolution>
                </range>
                <noise>
                  <type>none</type>
                  <mean>0</mean>
                  <stddev>0</stddev>
                </noise>
                <visibility_mask>4294967295</visibility_mask>
              </lidar>
            </sensor>
            <enable_wind>false</enable_wind>
          </link>
    
          <joint name='lidar_joint' type='fixed'>
            <pose relative_to="lidar"/>
            <parent>chassis</parent>
            <child>lidar</child>
          </joint>

          <link name='ultrasonic'>
            <pose relative_to='chassis'>0.07 0 -0.02 0 0 0</pose>
            <inertial>
                <mass>0.05</mass>
                <inertia>
                    <ixx>8.3333e-09</ixx>
                    <iyy>8.3333e-09</iyy>
                    <izz>8.3333e-09</izz>
                  </inertia>
            </inertial>
            <visual name='visual'>
                <geometry>
                  <box>
                    <size>0.01 0.01 0.01</size>
                  </box>
                </geometry>
                <material>
                    <ambient>0.9 0.9 0.9 1</ambient>
                    <diffuse>0.9 0.9 0.9 1</diffuse>
                    <specular>0.9 0.9 0.9 1</specular>
                </material>
              </visual>
            <collision name='collision'>
              <geometry>
                <box>
                  <size>0.01 0.01 0.01</size>
                </box>
              </geometry>
            </collision>

            <sensor name='gpu_lidar' type='gpu_lidar'>
              <pose relative_to="ultrasonic">0 0 0 0 0 0</pose>
              <topic>simulator_ultrasonic</topic>
              <update_rate>20</update_rate>
              <lidar>
                <scan>
                  <horizontal>
                    <samples>3</samples>
                    <resolution>1</resolution>
                    <min_angle>-0.1308</min_angle>
                    <max_angle>0.1308</max_angle>
                  </horizontal>
                  <vertical>
                    <samples>1</samples>
                    <resolution>1</resolution>
                    <min_angle>0</min_angle>
                    <max_angle>0</max_angle>
                  </vertical>
                </scan>
                <range>
                  <min>0.02</min>
                  <max>4</max>
                  <resolution>0.01</resolution>
                </range>
                <noise>
                  <type>none</type>
                  <mean>0</mean>
                  <stddev>0</stddev>
                </noise>
                <visibility_mask>4294967295</visibility_mask>
              </lidar>
            </sensor>
            <enable_wind>false</enable_wind>
          </link>
    
          <joint name='ultrasonic_joint' type='fixed'>
            <pose relative_to="ultrasonic"/>
            <parent>chassis</parent>
            <child>ultrasonic</child>
          </joint>
    
        <include>
          <name>left</name>
          <uri>/home/daniel/ros2_ws/src/gazebo_simulator_nodes/models/line_tracking.sdf</uri>
          <pose relative_to='chassis'>0.06 0.03 -0.0375 0 1.57 0</pose>
        </include>

        <joint name='line_tracking_left_joint' type='fixed'>
            <pose relative_to='left'/>
            <parent>chassis</parent>
            <child>left::line_tracking</child>
        </joint>

        <include>
          <name>middle</name>
          <uri>/home/daniel/ros2_ws/src/gazebo_simulator_nodes/models/line_tracking.sdf</uri>
          <pose relative_to='chassis'>0.06 0 -0.0375 0 1.57 0</pose>
        </include>

        <joint name='line_tracking_middle_joint' type='fixed'>
            <pose relative_to='middle'/>
            <parent>chassis</parent>
            <child>middle::line_tracking</child>
        </joint>
            
        <include>
          <name>right</name>
          <uri>/home/daniel/ros2_ws/src/gazebo_simulator_nodes/models/line_tracking.sdf</uri>
          <pose relative_to='chassis'>0.06 -0.03 -0.0375 0 1.57 0</pose>
        </include>

        <joint name='line_tracking_right_joint' type='fixed'>
            <pose relative_to='right'/>
            <parent>chassis</parent>
            <child>right::line_tracking</child>
        </joint>

        <include>
            <name>left_front_wheel</name>
            <uri>/home/daniel/ros2_ws/src/gazebo_simulator_nodes/models/wheel.sdf</uri>
            <pose relative_to="chassis">0.03 0.075 -0.025 -1.5707 0 0</pose>
        </include>

        <joint name='left_front_wheel_joint' type='revolute'>
            <pose relative_to='left_front_wheel'/>
            <parent>chassis</parent>
            <child>left_front_wheel::wheel</child>
            <axis>
                <xyz>0 0 1</xyz>
                <limit>
                    <lower>-1.79769e+308</lower>
                    <upper>1.79769e+308</upper>
                </limit>
            </axis>
        </joint>

        <include>
            <name>right_front_wheel</name>
            <uri>/home/daniel/ros2_ws/src/gazebo_simulator_nodes/models/wheel.sdf</uri>
            <pose relative_to="chassis">0.03 -0.075 -0.025 -1.5707 0 0</pose>
        </include>

        <joint name='right_front_wheel_joint' type='revolute'>
            <pose relative_to='right_front_wheel'/>
            <parent>chassis</parent>
            <child>right_front_wheel::wheel</child>
            <axis>
                <xyz>0 0 1</xyz>
                <limit>
                    <lower>-1.79769e+308</lower>
                    <upper>1.79769e+308</upper>
                </limit>
            </axis>
        </joint>

        <include>
            <name>left_rear_wheel</name>
            <uri>/home/daniel/ros2_ws/src/gazebo_simulator_nodes/models/wheel.sdf</uri>
            <pose relative_to="chassis">-0.055 0.075 -0.025 -1.5707 0 0</pose>
        </include>

        <joint name='left_rear_wheel_joint' type='revolute'>
            <pose relative_to='left_rear_wheel'/>
            <parent>chassis</parent>
            <child>left_rear_wheel::wheel</child>
            <axis>
                <xyz>0 0 1</xyz>
                <limit>
                    <lower>-1.79769e+308</lower>
                    <upper>1.79769e+308</upper>
                </limit>
            </axis>
        </joint>

        <include>
            <name>right_rear_wheel</name>
            <uri>/home/daniel/ros2_ws/src/gazebo_simulator_nodes/models/wheel.sdf</uri>
            <pose relative_to="chassis">-0.055 -0.075 -0.025 -1.5707 0 0</pose>
        </include>

        <joint name='right_rear_wheel_joint' type='revolute'>
            <pose relative_to='right_rear_wheel'/>
            <parent>chassis</parent>
            <child>right_rear_wheel::wheel</child>
            <axis>
                <xyz>0 0 1</xyz>
                <limit>
                    <lower>-1.79769e+308</lower>
                    <upper>1.79769e+308</upper>
                </limit>
            </axis>
        </joint>

    <plugin name='ignition::gazebo::systems::DiffDrive' filename='libignition-gazebo-diff-drive-system.so'>
        <left_joint>left_front_wheel_joint</left_joint>
        <right_joint>right_front_wheel_joint</right_joint>
        <wheel_separation>0.15</wheel_separation>
        <wheel_radius>0.035</wheel_radius>
        <odom_publish_frequency>1</odom_publish_frequency>
    </plugin>

    <plugin name='ignition::gazebo::systems::DiffDrive' filename='libignition-gazebo-diff-drive-system.so'>
        <left_joint>left_rear_wheel_joint</left_joint>
        <right_joint>right_rear_wheel_joint</right_joint>
        <wheel_separation>0.15</wheel_separation>
        <wheel_radius>0.035</wheel_radius>
        <odom_publish_frequency>1</odom_publish_frequency>
    </plugin>

</model>
</sdf>